<?xml version="1.0"?>
<robot xmlns:xacro="http://www.ros.org/wiki/xacro" name="rover">
    

    <link name="base_link">
        <inertial>
            <origin xyz="0.0 0.0 0.0" rpy="0.0 0.0 0.0"/>
            <mass value="0.0"/>
            <inertia ixx="0.0" ixy="0.0" ixz="0.0" iyy="0.0" iyz="0.0" izz="0.0"/>
        </inertial>
        <visual name="">
            <origin xyz="0.0 0.0 0.0" rpy="0.0 0.0 0.0"/>
            <geometry>
                <box size="1.75 3.4 0.1"/>
            </geometry>
            <material name="red">
                <color rgba="1.0 0.0 0.0 1.0"/>
                <texture fillname=""/>
            </material> 
        </visual>
<collision>
    <origin xyz="0.0 0.0 0.0" rpy="0.0 0.0 0.0"/>
    <geometry>
        <box size="0.0 0.0 0.0"/>
    </geometry>
</collision>
    </link>

<joint name="base_joint" type="fixed">
    <origin xyz="0.0 0.0 0.5" rpy="0.0 0.0 0.0"/>
    <parent link="base_footprint"/>
    <child link="base_link"/>
    <axis xyz="0.0 0.0 0.0"/>
</joint>

<xacro:property name="side" value="left"/>
 
 
  <link name="${side}_wheel">
        <inertial>
            <origin xyz="0.0 0.0 0.0" rpy="0.0 0.0 0.0"/>
            <mass value="0.0"/>
            <inertia ixx="0.0" ixy="0.0" ixz="0.0" iyy="0.0" iyz="0.0" izz="0.0"/>
        </inertial>
        <visual name="">
            <origin xyz="0.0 0.0 0.0" rpy="0.0 0.0 0.0"/>
            <geometry>
               <cylinder radius="0.5" length="0.2"/>
            </geometry>
            <material name="green">
                <color rgba="0.0 1.0 0.0 1.0"/>
                <texture fillname=""/>
            </material> 
        </visual>
<collision>
    <origin xyz="0.0 0.0 0.0" rpy="0.0 0.0 0.0"/>
    <geometry>
               <cylinder radius="0.5" length="0.1"/>
    </geometry>
</collision>
    </link>

<joint name="${side}_wheel_joint" type="continuous">
    <origin xyz="1.0 1.3 0.0" rpy="0.0 1.57 0.0"/>
    <parent link="base_link"/>
    <child link="${side}_wheel"/>
    <axis xyz="1.0 0.0 0.0"/>
</joint>


 <link name="right_wheel">
        <inertial>
            <origin xyz="0.0 0.0 0.0" rpy="0.0 0.0 0.0"/>
            <mass value="0.0"/>
            <inertia ixx="0.0" ixy="0.0" ixz="0.0" iyy="0.0" iyz="0.0" izz="0.0"/>
        </inertial>
        <visual name="">
            <origin xyz="0.0 0.0 0.0" rpy="0.0 0.0 0.0"/>
            <geometry>
               <cylinder radius="0.5" length="0.2"/>
            </geometry>
            <material name="blue">
                <color rgba="0.0 0.0 1.0 1.0"/>
                <texture fillname=""/>
            </material> 
        </visual>
<collision>
    <origin xyz="0.0 0.0 0.0" rpy="0.0 0.0 0.0"/>
    <geometry>
               <cylinder radius="0.5" length="0.1"/>
    </geometry>
</collision>
    </link>

<joint name="right_wheel_joint" type="continuous">
    <origin xyz="-1.0 1.3 0.0" rpy="0.0 1.57 0.0"/>
    <parent link="base_link"/>
    <child link="right_wheel"/>
    <axis xyz="1.0 0.0 0.0"/>
</joint>

 <link name="left_wheel2">
        <inertial>
            <origin xyz="0.0 0.0 0.0" rpy="0.0 0.0 0.0"/>
            <mass value="0.0"/>
            <inertia ixx="0.0" ixy="0.0" ixz="0.0" iyy="0.0" iyz="0.0" izz="0.0"/>
        </inertial>
        <visual name="">
            <origin xyz="0.0 0.0 0.0" rpy="0.0 0.0 0.0"/>
            <geometry>
               <cylinder radius="0.5" length="0.2"/>
            </geometry>
            <material name="blue">
                <color rgba="0.0 0.0 1.0 1.0"/>
                <texture fillname=""/>
            </material> 
        </visual>
<collision>
    <origin xyz="0.0 0.0 0.0" rpy="0.0 0.0 0.0"/>
    <geometry>
               <cylinder radius="0.5" length="0.1"/>
    </geometry>
</collision>
    </link>

<joint name="left_wheel_joint2" type="continuous">
    <origin xyz="1.0 -1.3 0.0" rpy="0.0 1.57 0.0"/>
    <parent link="base_link"/>
    <child link="left_wheel2"/>
    <axis xyz="1.0 0.0 0.0"/>
</joint>

 <link name="right_wheel2">
        <inertial>
            <origin xyz="0.0 0.0 0.0" rpy="0.0 0.0 0.0"/>
            <mass value="0.0"/>
            <inertia ixx="0.0" ixy="0.0" ixz="0.0" iyy="0.0" iyz="0.0" izz="0.0"/>
        </inertial>
        <visual name="">
            <origin xyz="0.0 0.0 0.0" rpy="0.0 0.0 0.0"/>
            <geometry>
               <cylinder radius="0.5" length="0.2"/>
            </geometry>
            <material name="green">
                <color rgba="0.0 1.0 0.0 1.0"/>
                <texture fillname=""/>
            </material> 
        </visual>
<collision>
    <origin xyz="0.0 0.0 0.0" rpy="0.0 0.0 0.0"/>
    <geometry>
               <cylinder radius="0.5" length="0.1"/>
    </geometry>
</collision>
    </link>

<joint name="right_wheel_joint2" type="continuous">
    <origin xyz="-1.0 -1.3 0.0" rpy="0.0 1.57 0.0"/>
    <parent link="base_link"/>
    <child link="right_wheel2"/>
    <axis xyz="1.0 0.0 0.0"/>
</joint>

 


<link name="base_footprint">

</link>


</robot>