<?xml version="1.0"?>
<robot xmlns:xacro="http://www.ros.org/wiki/xacro" name="rover">

  <gazebo>
    <plugin name="gazebo_ros_control" filename="libgazebo_ros_control.so">
      <robotNamespace>/</robotNamespace>
    </plugin>
  </gazebo>

  <xacro:macro name="default_inertial" params="mass">
    <inertial>
      <mass value="${mass}" />
      <inertia ixx="1.0" ixy="0.0" ixz="0.0" iyy="1.0" iyz="0.0" izz="1.0" />
    </inertial>
  </xacro:macro>


<link name="base_link">
      <visual>
        <geometry>
            <box size="1.75 3.4 0.1"/>
        </geometry>
        <material name="red">
          <color rgba="1.0 0.0 0.0 1.0"/>
          <texture fillname=""/>
        </material> 
      </visual>
      <collision>
        <geometry>
          <box size="1.75 3.4 0.1"/>
        </geometry>
      </collision>
  <xacro:default_inertial mass="10"/>
</link>

<xacro:macro name="wheel" params="name x y reflect">
    
  <link name="${name}_wheel">
    <origin xyz="0.0 0.0 0.0" rpy="0.0 0.0 0.0"/>
    <xacro:default_inertial mass="1"/>
    <visual name="">
      <origin xyz="0.0 0.0 0.0" rpy="0.0 0.0 0.0"/>
      <geometry>
        <cylinder radius="0.5" length="0.2"/>
      </geometry>
      <material name="blue">
        <color rgba="0.0 0.0 1.0 1.0"/>
      </material> 
    </visual>
  <collision>
      <origin xyz="0.0 0.0 0.0" rpy="0.0 0.0 0.0"/>
      <geometry>
                <cylinder radius="0.5" length="0.1"/>
      </geometry>
  </collision>
  </link>

  <joint name="${name}_wheel_joint" type="continuous">
      <origin xyz="${reflect*x} ${y} 0.0" rpy=" 0.0 1.57 0.0"/>
      <parent link="base_link"/>
      <child link="${name}_wheel"/>
      <axis xyz="0.0 0.0 1.0" rpy="0 0 0"/>
  </joint>

    <gazebo reference="${name}_wheel">
        <mu1 value="200.0"/>
        <mu2 value="100.0"/>
        <kp value="10000000.0" />
        <kd value="1.0" />
        <material>Gazebo/Grey</material>
    </gazebo>

    <transmission name="${name}_wheel_trans">
      <type>transmission_interface/SimpleTransmission</type>
      <actuator name="${name}_wheel_motor">
        <mechanicalReduction>1</mechanicalReduction>
      </actuator>
      <joint name="${name}_wheel_joint">
        <hardwareInterface>hardware_interface/VelocityJointInterface</hardwareInterface>
      </joint>
    </transmission>
    
</xacro:macro>

<xacro:wheel name="front_right" x="1.0" y="1.3" reflect="1"/>
<xacro:wheel name="front_left" x="-1.0" y="1.3" reflect="1"/>
<xacro:wheel name="back_right" x="-1.0" y="-1.3" reflect="-1"/>
<xacro:wheel name="back_left" x="1.0" y="-1.3" reflect="-1"/>




</robot>